Workbook

Sheet Overview

Sheet Net Worth Monthly
A1: FX Rate | B1: =IFERROR(__xludf.DUMMYFUNCTION("googlefinance(""Currency:USDCAD"")"),1.42464998) -> 1.42465
A2: Tax Rate | B2: 0.5
A4: Assets | B4: Jan | C4: Feb | D4: Mar | E4: Jul | F4: Aug | G4: Dec | H4: 45315 | I4: June | J4: October | K4: December | L4: January | M4: June | N4: July | O4: August | P4: December | Q4: February | R4: June | S4: July | T4: August | U4: 2026 Performance | V4: 2025 Performance | W4: All-Time Performance
A5: Cash
A6: RBC Savings | B6: 160000 | C6: 255336 | D6: 244385 | E6: 103923 | F6: 86000 | G6: 84243 | H6: 84500 | I6: 156000 | J6: 12284 | K6: 35000 | L6: 52000 | M6: 228000 | N6: 215000 | O6: 213275 | P6: 348047 | Q6: 328000 | R6: 353000 | S6: 325000 | T6: 276598 | U6: =(T6-Q6)/Q6 -> -0.15671341 | V6: =(P6-L6)/L6 -> 5.6932115 | W6: =(T6-B6)/B6 -> 0.7287375
A7: RBC Chequing | B7: 2000 | C7: 0 | D7: 0 | E7: 45.83 | F7: 45.83 | G7: 0 | H7: 0 | I7: 0 | J7: 71.34 | K7: 21655 | L7: 10000 | M7: 56000 | N7: 75000 | O7: 71306 | P7: 83267 | Q7: 48700 | R7: 12424 | S7: 0 | T7: 45138 | U7: =(T7-Q7)/Q7 -> -0.073141684 | V7: =(P7-L7)/L7 -> 7.3267 | W7: =(T7-B7)/B7 -> 21.569
A8: Chase | B8: =95000*B1 -> 135341.75 | C8: 0 | D8: =8000*B1 -> 11397.2 | E8: 18555 | F8: =23000*B1 -> 32766.95 | G8: 113598 | H8: =113000*B1 -> 160985.45 | I8: 22000 | J8: =(15000*B1) -> 21369.75 | K8: =2000*B1 -> 2849.3 | L8: 0 | M8: 2000 | N8: 52000 | O8: =42000*B1 -> 59835.299 | P8: =45000*B1 -> 64109.249 | Q8: =52000*B1 -> 74081.799 | R8: =62000*B1 -> 88328.299 | S8: =60000*B1 -> 85478.999 | T8: =63000*B1 -> 89752.949 | U8: =(T8-Q8)/Q8 -> 0.21153846 | V8: =(P8-L8)/L8 -> #DIV/0! | W8: =(T8-B8)/B8 -> -0.33684211
A9: RBC Savings | B9: 2000 | C9: 0 | D9: 0 | E9: 0 | F9: 0 | G9: 0 | H9: 0 | I9: 0 | J9: 0 | K9: 0 | L9: 0 | M9: 0 | N9: 0 | O9: 0 | P9: 0 | Q9: 0 | R9: 0 | S9: 0 | T9: 0 | U9: =(T9-Q9)/Q9 -> #DIV/0! | V9: =(P9-L9)/L9 -> #DIV/0! | W9: =(T9-B9)/B9 -> -1
A10: Chase - Lisa | B10: =2500*B1 -> 3561.6249 | C10: =2500*B1 -> 3561.6249 | D10: =2500*B1 -> 3561.6249 | E10: =2500*$B$1 -> 3561.6249 | F10: =2500*$B$1 -> 3561.6249 | G10: 3000 | H10: 3000 | I10: 3000 | J10: 3000 | K10: 3000 | L10: 3000 | M10: =13000*B1 -> 18520.45 | N10: =5000 -> 5000 | O10: 5000 | P10: =2800*B1 -> 3989.0199 | Q10: 3000 | R10: =10000*B1 -> 14246.5 | S10: =10000*B1 -> 14246.5 | T10: 4000 | U10: =(T10-Q10)/Q10 -> 0.33333333 | V10: =(P10-L10)/L10 -> 0.32967331 | W10: =(T10-B10)/B10 -> 0.12308288
A11: RBC Savings - Lisa | B11: 6000 | C11: 6000 | D11: 6000 | E11: 6000 | F11: 6000 | G11: 6000 | H11: 6000 | I11: 6000 | J11: 6000 | K11: 6000 | L11: 6000 | M11: 6000 | N11: 6000 | O11: 6000 | P11: 6000 | Q11: 6000 | R11: 6000 | S11: 6000 | T11: 6000 | U11: =(T11-Q11)/Q11 -> 0 | V11: =(P11-L11)/L11 -> 0 | W11: =(T11-B11)/B11 -> 0
A12: RBC TFSA | B12: 10000 | C12: 10000 | D12: 10000 | E12: 10000 | F12: 10000 | G12: 10000 | H12: 10000 | I12: 10000 | J12: 10000 | K12: 10000 | L12: 10000 | M12: 24000 | N12: 24195 | O12: 24195 | P12: 24195 | Q12: 24244 | R12: 24244 | S12: 24244 | T12: 24286 | U12: =(T12-Q12)/Q12 -> 0.0017323874 | V12: =(P12-L12)/L12 -> 1.4195 | W12: =(T12-B12)/B12 -> 1.4286
A13: Wealthsimple | T13: 5000 | U13: =(T13-Q13)/Q13 -> #DIV/0! | V13: =(P13-L13)/L13 -> #DIV/0! | W13: =(T13-B13)/B13 -> #DIV/0!
A14: Total Cash | B14: =SUM(B6:B12) -> 318903.37 | C14: =SUM(C6:C12) -> 274897.62 | D14: =SUM(D6:D12) -> 275343.82 | E14: =SUM(E6:E12) -> 142085.45 | F14: =SUM(F6:F12) -> 138374.4 | G14: =SUM(G6:G12) -> 216841 | H14: =SUM(H6:H12) -> 264485.45 | I14: =SUM(I6:I12) -> 197000 | ... Q14: =SUM(Q6:Q12) -> 484025.8 | R14: 493180 | S14: =SUM(S6:S12) -> 454969.5 | T14: =sum(T6:T13) -> 450774.95 | U14: =(R14-P14)/P14 -> -0.068781664 | V14: =(P14-L14)/L14 -> 5.5383613 | W14: =(T14-B14)/B14 -> 0.41351578
A15: Investments
A16: Fidelity | B16: =120000*B1 -> 170958 | C16: =128000*B1 -> 182355.2 | D16: =129000*B1 -> 183779.85 | E16: =139000*B1 -> 198026.35 | F16: =132000*B1 -> 188053.8 | G16: =141935*B1 -> 202207.69 | H16: =(142126*B1)*0.7 -> 141735.86 | I16: =(172000*B1)*0.7 -> 171527.86 | J16: 170000 | K16: =(192992*B1) -> 274946.05 | L16: =196246*B1 -> 279581.86 | M16: =(200000*B1) -> 284930 | N16: =(211000*B1) -> 300601.15 | O16: =(219000*B1) -> 311998.35 | P16: =249000*B1 -> 354737.84 | Q16: =257000*B1 -> 366135.04 | R16: =271000*1.39 -> 376690 | S16: =278600*1.39 -> 387254 | T16: =287827*B1 -> 410052.73 | U16: =(T16-Q16)/Q16 -> 0.11994942 | V16: =(P16-L16)/L16 -> 0.26881567 | W16: =(T16-B16)/B16 -> 1.3985583
A17: Questrade | B17: 23000 | C17: 23370 | D17: 22964 | E17: 24692 | F17: 24654 | G17: 25906 | H17: 26832 | I17: 28462 | J17: 29626 | K17: 32000 | L17: 32313 | M17: =32313 -> 32313 | N17: =35000 -> 35000 | O17: 37486.32 | P17: 36765 | Q17: 34451 | R17: 36000 | S17: 37000 | T17: 39000 | U17: =(T17-Q17)/Q17 -> 0.13204261 | V17: =(P17-L17)/L17 -> 0.13777737 | W17: =(T17-B17)/B17 -> 0.69565217
A18: RBC Dom Reg | B18: 94684 | C18: 99922 | D18: 96597 | E18: 96280 | G18: 101995 | H18: 103948 | I18: 105878 | J18: 115475 | K18: 127000 | L18: 125410 | M18: 125410 | N18: 115300 | O18: 118457 | P18: 110048 | Q18: 117991 | R18: 110793 | S18: 119573 | T18: 119926 | U18: =(T18-Q18)/Q18 -> 0.016399556 | V18: =(P18-L18)/L18 -> -0.12249422 | W18: =(T18-B18)/B18 -> 0.26659203
A19: RBC Dom Non Reg | B19: 143279 | C19: 156163 | D19: 162323 | E19: =218343 -> 218343 | G19: 235931 | H19: 237748 | I19: 251877 | J19: 275066 | K19: 280000 | L19: =282301 -> 282301 | M19: =282301 -> 282301 | N19: 291000 | O19: 297502 | P19: 321208 | Q19: 331999 | R19: 363590 | S19: 375872 | T19: 383108 | U19: =(T19-Q19)/Q19 -> 0.15394323 | V19: =(P19-L19)/L19 -> 0.13782098 | W19: =(T19-B19)/B19 -> 1.6738601
A20: RBC Dom - *400 | B20: 95125 | C20: 99219 | D20: 94216 | E20: 103130 | G20: 109081 | H20: 112359 | I20: 119264 | J20: 127805 | K20: 134000 | L20: 137803 | M20: =137803 -> 137803 | N20: 138650 | O20: 137748 | P20: 141822 | Q20: 140942 | R20: 143819 | S20: 150866 | T20: 154949 | U20: =(T20-Q20)/Q20 -> 0.099381306 | V20: =(P20-L20)/L20 -> 0.029164822 | W20: =(T20-B20)/B20 -> 0.62889882
A21: RBC Dom - *605 | B21: 56769 | C21: 59228 | D21: 56260 | E21: 61845 | G21: 65416 | H21: 67242 | I21: 71239 | J21: 76453 | K21: 80000 | L21: 82211 | M21: 82211 | N21: 82699 | O21: 82020 | P21: 84284 | Q21: 83742 | R21: 85597 | S21: 89727 | T21: 92067 | U21: =(T21-Q21)/Q21 -> 0.099412481 | V21: =(P21-L21)/L21 -> 0.025215604 | W21: =(T21-B21)/B21 -> 0.62178302
A22: 401K Lisa | B22: =75000*B1 -> 106848.75 | C22: 101000 | D22: =77000*B1 -> 109698.05 | E22: =90000*B1 -> 128218.5 | F22: =92000*B1 -> 131067.8 | G22: 130000 | H22: =(114000*B1)*0.7 -> 113687.07 | I22: =120000 -> 120000 | J22: =(143000*B1)*0.7 -> 142607.46 | K22: =(170000*B1) -> 242190.5 | L22: =197000*B1 -> 280656.05 | M22: =(197000*B1) -> 280656.05 | N22: =(197000*B1) -> 280656.05 | O22: =(197000*B1) -> 280656.05 | P22: =208889*B1 -> 297593.71 | Q22: =210000*1.39 -> 291900 | R22: =238000*B1 -> 339066.7 | S22: =220000*B1 -> 313423 | T22: =257000*B1 -> 366135.04 | U22: =(T22-Q22)/Q22 -> 0.2543167 | V22: =(P22-L22)/L22 -> 0.060350254 | W22: =(T22-B22)/B22 -> 2.4266667
A23: SunLife | K23: 8000 | L23: 9000 | M23: 12000 | N23: 20000 | O23: 45785 | P23: 59000 | Q23: 64824 | R23: 80792 | S23: 86441 | T23: 91500 | U23: =(T23-Q23)/Q23 -> 0.41151425 | V23: =(N23-L23)/L23 -> 1.2222222 | W23: =(T23-B23)/B23 -> #DIV/0!
A24: Total Investments | B24: =SUM(B16:B22) -> 690663.75 | C24: =SUM(C16:C22) -> 721257.2 | D24: =SUM(D16:D22) -> 725837.9 | E24: =SUM(E16:E22) -> 830534.85 | F24: =SUM(F16:F22) -> 343775.6 | G24: =SUM(G16:G22) -> 870536.69 | H24: =SUM(H16:H22) -> 803551.93 | I24: =SUM(I16:I22) -> 868247.86 | J24: =SUM(J18:J22) -> 737406.46 | K24: =SUM(K16:K23) -> 1178136.5 | L24: =Sum(L16:L23) -> 1229275.9 | M24: =Sum(M16:M23) -> 1237624 | N24: =Sum(N16:N23) -> 1263906.2 | O24: =SUM(O16:O23) -> 1311652.7 | P24: =SUM(P16:P23) -> 1405458.6 | Q24: =SUM(Q16:Q23) -> 1431984 | R24: 1512944 | S24: =SUM(S16:S23) -> 1560156 | T24: =sum(T16:T23) -> 1656737.8 | U24: =(T24-Q24)/Q24 -> 0.15695268 | V24: =(P24-L24)/L24 -> 0.1433223 | W24: =(T24-B24)/B24 -> 1.3987617
A25: Deferred Items
A26: Shareworks | B26: =160000*B2 -> 80000 | C26: =167770*B2 -> 83885 | D26: =168264*B2 -> 84132 | E26: 127000 | F26: =245668*B2 -> 122834 | G26: =461429*B2 -> 230714.5 | H26: =457967*B2 -> 228983.5 | I26: =528000*B2 -> 264000 | J26: =611000*B2 -> 305500 | K26: =(418147+275000)*B2 -> 346573.5 | L26: =715000*B2 -> 357500 | M26: =(800000+200000)*B2 -> 500000 | N26: =(800000+200000)*B2 -> 500000 | O26: =(893000+200000)*0.5 -> 546500 | P26: =(1767000)*0.5 -> 883500 | Q26: =1736000*0.5 -> 868000 | R26: =2100000*0.5 -> 1050000 | S26: =2213597*0.5 -> 1106798.5 | T26: =2290629*B2 -> 1145314.5 | U26: =(T26-Q26)/Q26 -> 0.31948675 | V26: =(P26-L26)/L26 -> 1.4713287 | W26: =(T26-B26)/B26 -> 13.316431
A27: RBC DB | B27: =200000*B2 -> 100000 | C27: =200000*B2 -> 100000 | D27: =200000*B2 -> 100000 | E27: =200000*B2 -> 100000 | F27: =200000*B2 -> 100000 | G27: =200000*B2 -> 100000 | H27: =200000*B2 -> 100000 | I27: 100000 | J27: =200000*B2 -> 100000 | K27: =200000*B2 -> 100000 | L27: 100000 | M27: 100000 | N27: 115000 | O27: 115000 | P27: 115000 | Q27: =120000 -> 120000 | R27: 120000 | S27: 180000 | T27: =180000 -> 180000 | U27: =(T27-Q27)/Q27 -> 0.5 | V27: =(N27-L27)/L27 -> 0.15 | W27: =(T27-B27)/B27 -> 0.8
A28: After Tax Total Deferred | B28: =SUM(B26:B27) -> 180000 | C28: =SUM(C26:C27) -> 183885 | D28: =SUM(D26:D27) -> 184132 | E28: =SUM(E26:E27) -> 227000 | F28: =SUM(F26:F27) -> 222834 | G28: =sum(G26:G27) -> 330714.5 | H28: =sum(H26:H27) -> 328983.5 | I28: =sum(I26:I27) -> 364000 | J28: =SUM(J26:J27) -> 405500 | K28: =SUM(K26:K27) -> 446573.5 | L28: =Sum(L26:L27) -> 457500 | M28: =Sum(M26:M27) -> 600000 | N28: =Sum(N26:N27) -> 615000 | O28: =SUM(O26:O27) -> 661500 | P28: =SUM(P26:P27) -> 998500 | Q28: =SUM(Q26:Q27) -> 988000 | R28: 1131500 | S28: =SUM(S26:S27) -> 1286798.5 | T28: =sum(T26:T27) -> 1325314.5 | U28: =(T28-Q28)/Q28 -> 0.34141144 | V28: =(P28-L28)/L28 -> 1.1825137 | W28: =(T28-B28)/B28 -> 6.3628583
A29: Fixed Assets
A30: House | B30: 800000 | C30: 800000 | D30: 800000 | E30: 850000 | F30: 850000 | G30: 900000 | H30: 900000 | I30: 900000 | J30: 900000 | K30: 900000 | L30: 900000 | M30: 900000 | N30: 900000 | O30: 900000 | P30: 800000 | Q30: 850000 | R30: 850000 | S30: 850000 | T30: 850000 | U30: =(T30-Q30)/Q30 -> 0 | V30: =(P30-L30)/L30 -> -0.11111111 | W30: =(T30-B30)/B30 -> 0.0625
A31: 31 old brewery | I31: 1350000 | J31: 1350000 | K31: 1350000 | L31: 1350000 | M31: 1350000 | N31: 1350000 | O31: 1350000 | P31: 1350000 | Q31: 1350000 | R31: 1350000 | S31: 1375000 | T31: 1375000 | U31: =(T31-Q31)/Q31 -> 0.018518519 | V31: =(P31-L31)/L31 -> 0 | W31: =(T31-B31)/B31 -> #DIV/0!
A32: Car | B32: 15000 | C32: 15000 | D32: 15000 | E32: 10000 | F32: 10000 | G32: 10000 | H32: 10000 | I32: 10000 | J32: 5000 | K32: 5000 | L32: 5000 | M32: 5000 | N32: 5000 | O32: 5000 | P32: 5000 | Q32: 5000 | R32: 5000 | S32: 5000 | T32: 5000 | U32: =(T32-Q32)/Q32 -> 0 | V32: =(P32-L32)/L32 -> 0 | W32: =(T32-B32)/B32 -> -0.66666667
A33: Motorcycle | C33: 25000 | D33: 25000 | E33: 25000 | F33: 25000 | G33: 25000 | H33: 25000 | I33: 25000 | J33: 25000 | K33: 25000 | L33: 22000 | M33: 22000 | N33: 22000 | O33: 22000 | P33: 22000 | Q33: 18000 | R33: 18000 | S33: 18000 | T33: 18000 | U33: =(T33-Q33)/Q33 -> 0 | V33: =(P33-L33)/L33 -> 0 | W33: =(T33-B33)/B33 -> #DIV/0!
A34: Total Fixed Assets | B34: =SUM(B30:B32) -> 815000 | C34: =SUM(C30:C33) -> 840000 | D34: =SUM(D30:D33) -> 840000 | E34: =SUM(E30:E33) -> 885000 | F34: =SUM(F30:F33) -> 885000 | G34: =SUM(G30:G33) -> 935000 | H34: =SUM(H30:H33) -> 935000 | I34: =SUM(I30:I33) -> 2285000 | J34: =SUM(J30:J33) -> 2280000 | ... S34: =SUM(S30:S33) -> 2248000 | T34: =sum(T30:T33) -> 2248000 | U34: =(T34-Q34)/Q34 -> 0.011246064 | V34: =(P34-L34)/L34 -> -0.043917435 | W34: =(T34-B34)/B34 -> 1.7582822
A35: Total Assets | B35: =SUM(B14,B24,B28,B34) -> 2004567.1 | C35: =SUM(C14,C24,C28,C34) -> 2020039.8 | D35: =sum(D24,D28,D14,D34) -> 2025313.7 | E35: =sum(E24,E28,E14,E34) -> 2084620.3 | F35: =sum(F24,F28,F14,F34) -> 1589984 | G35: =sum(G24,G28,G14,G34) -> 2353092.2 | H35: =SUM(H14,H24,H28,H34) -> 2332020.9 | I35: =SUM(I14,I24,I28,I34) -> 3714247.9 | J35: =SUM(J14,J24,J28,J34) -> 3475631.6 | K35: =SUM(K14,K24,K28,K34) -> 3983214.3 | L35: =SUM(L14,L24,L28,L34) -> 4044775.9 | M35: =SUM(M14,M24,M28,M34) -> 4449144.5 | N35: =SUM(N14,N24,N28,N34) -> 4533101.2 | O35: =SUM(O14,O24,O28,O34) -> 4629764 | ... T35: =SUM(T14,T24,T28,T34) -> 5680827.2 | U35: =(T35-Q35)/Q35 -> 0.10801957 | V35: =(P35-L35)/L35 -> 0.26349789 | W35: =(T35-B35)/B35 -> 1.8339421
A37: Liabilities
A38: Mortgage - 200 Queen St | B38: 265000 | C38: 264273 | D38: 263785.48 | E38: 258391 | F38: 255000 | G38: 252000 | H38: 251000 | I38: 246900 | J38: 245000 | K38: 239000 | L38: 238402 | M38: 238402 | N38: 232000 | O38: 230000 | P38: 584000 | Q38: 580000 | R38: 574000 | S38: 573000 | T38: 570546 | U38: =(T38-Q38)/Q38 -> -0.0163 | V38: =(P38-L38)/L38 -> 1.4496439 | W38: =(T38-B38)/B38 -> 1.1530038
A39: Mortgage - 31 Old Brewery | I39: 1080000 | J39: 1077842 | K39: 1077842 | L39: 1074000 | M39: 1074000 | N39: 1071000 | O39: 1070000 | P39: 587000 | Q39: 584000 | R39: 583000 | S39: 582000 | T39: 581167 | U39: =(T39-Q39)/Q39 -> -0.0048510274 | V39: =(P39-L39)/L39 -> -0.45344507 | W39: =(T39-I39)/I39 -> -0.46188241
A40: Credit Line
A41: Total Liabilities | B41: =SUM(B38) -> 265000 | C41: =SUM(C38) -> 264273 | D41: =sum(D38) -> 263785.48 | E41: =sum(E38) -> 258391 | F41: =sum(F38) -> 255000 | G41: =sum(G38) -> 252000 | H41: =sum(H38:H39) -> 251000 | I41: =sum(I38:I39) -> 1326900 | J41: =sum(J38:J39) -> 1322842 | K41: =SUM(K38:K40) -> 1316842 | L41: =SUM(L38:L40) -> 1312402 | M41: =SUM(M38:M40) -> 1312402 | N41: =SUM(N38:N40) -> 1303000 | O41: =SUM(O38:O40) -> 1300000 | P41: =SUM(P38:P40) -> 1171000 | Q41: =SUM(Q38:Q40) -> 1164000 | R41: =SUM(R38:R40) -> 1157000 | S41: =SUM(S38:S40) -> 1155000 | T41: =sum(T38:T39) -> 1151713 | U41: =(T41-Q41)/Q41 -> -0.010555842 | V41: =(P41-L41)/L41 -> -0.1077429 | W41: =(T41-B41)/B41 -> 3.3460868
A43: Overall Net Worth | B43: =B35-B41 -> 1739567.1 | C43: =C35-C41 -> 1755766.8 | D43: =D35-D41 -> 1761528.2 | E43: =sum(E35-E41) -> 1826229.3 | F43: =sum(F35-F41) -> 1334984 | G43: =sum(G35-G41) -> 2101092.2 | H43: =H35-H41 -> 2081020.9 | I43: =I35-I41 -> 2387347.9 | J43: =sum(J35-J41) -> 2152789.6 | K43: =sum(K35-K41) -> 2666372.3 | L43: =sum(L35-L41) -> 2732373.9 | M43: =sum(M35-M41) -> 3136742.5 | N43: =sum(N35-N41) -> 3230101.2 | O43: =sum(O35-O41) -> 3329764 | P43: =sum(P35-P41) -> 3939565.8 | Q43: =sum(Q35-Q41) -> 3963009.8 | ... T43: =sum(T35-T41) -> 4529114.2 | U43: =(T43-Q43)/Q43 -> 0.14284708 | V43: =(P43-L43)/L43 -> 0.44181066 | W43: =(T43-B43)/B43 -> 1.6035869

Sheet Inv Forecast - Data
A1: Rate of Return | B1: 0.05 | I1: Monthly (Gross) | J1: Annual Gross | K1: Monthly Net
A2: Monthly Contrib | B2: 3000 | G2: 2033 | I2: =J2/12 -> 23408.926 | J2: =E22*0.05 -> 280907.12 | K2: =I2*0.5 -> 11704.463
G3: 2036 | I3: =J3/12 -> 29725.842 | J3: =E25*0.05 -> 356710.1 | K3: =I3*0.5 -> 14862.921
A4: Equity | B4: ='Net Worth Monthly'!P34-'Net Worth Monthly'!P41 -> 1006000 | G4: CPP 55 | I4: 1600 | J4: =I4*12 -> 19200 | K4: =I4 -> 1600
A5: Annual Lump Sum 1 | B5: 200000 | G5: Pension 55 | I5: =J5/12 -> 3750 | J5: 45000 | K5: =I5*0.5 -> 1875
A6: Annual Lump Sum 2 | B6: 100000 | G6: Real Estate
A7: Retirement Withdrawal - High Risk | B7: 400000 | G7: 2033 | K7: =SUM(K2,K4,K5) -> 15179.463
A8: Retirement Withdrawal - Low Risk | B8: 200000 | G8: 2036 | K8: =sum(K3+K4+K5+K6) -> 18337.921
A11: Age | B11: Year | C11: Original Inv Value Fcst | D11: Actual Cash + Invest | E11: Investment + Cash + Outstanding | F11: Real Estate Value | G11: Forecast Real Estate Liabilities | H11: Forecast Real Estate Net Equity | I11: Original Fcst Net Worth | J11: Actual Net Worth | K11: Actual & Outstanding Net Worth
A12: 42 | B12: 2023 | C12: =674836 -> 674836 | E12: 859355.06 | I12: 1794603.7 | J12: 2089910.6
A13: 43 | B13: 2024 | C13: =(FV(0.05,1,-(12*$B$2),-C12,0))+$B$5 -> 944577.8 | E13: ='Net Worth Monthly'!K24+'Net Worth Monthly'!K14+'Net Worth Monthly'!K28 -> 1703214.3 | I13: 2421503.5 | J13: ='Net Worth Monthly'!K43 -> 2666372.3
A14: 44 | B14: 2025 | C14: 1227806.7 | D14: 1921463.3 | E14: 2919963.3 | F14: 2150000 | G14: ='Net Worth Monthly'!T41 -> 1151713 | H14: 979000 | I14: 2697025.6 | J14: 2900389.5 | K14: 3898889.5
A15: 45 | B15: 2026 | C15: =(FV(0.05,1,-(12*$B$2),-C14,0))+$B$5 -> 1525197 | D15: ='Net Worth Monthly'!T14+'Net Worth Monthly'!T24 -> 2107512.7 | E15: ='Net Worth Monthly'!T14+'Net Worth Monthly'!T24+(942691*0.5) -> 2578858.2 | F15: =FV(0.015,1,0,-F14,0) -> 2182250 | G15: =FV(-0.015,1,0,-G14,0) -> 1134437.3 | H15: =F15-G15 -> 1047812.7 | I15: 2985767.4 | J15: =('Net Worth Monthly'!T14+'Net Worth Monthly'!T24+'Net Worth Monthly'!T34)-('Net Worth Monthly'!T41) -> 3203799.7 | K15: ='Net Worth Monthly'!R43 -> 4203624
A16: 46 | B16: 2027 | C16: =(FV(0.05,1,-(12*$B$2),-C15,0))+$B$5 -> 1837456.9 | D16: =((FV(0.05,1,-(0),-D15,0))+$B$5) -> 2412888.4 | E16: =((FV(0.05,1,-(0),-E15,0))+(748000*0.5)) -> 3081801.1 | F16: =FV(0.015,1,0,-F15,0) -> 2214983.8 | G16: =FV(-0.01,1,0,-G15,0) -> 1123092.9 | H16: =F16-G16 -> 1091890.8 | I16: 3288379
A17: 47 | B17: 2028 | C17: =(FV(0.05,1,-(12*$B$2),-C16,0))+$B$5 -> 2165329.7 | D17: =((FV(0.05,1,-(0),-D16,0))+$B$5) -> 2733532.8 | E17: =((FV(0.05,1,-(0),-E16,0))+(600350*0.5)) -> 3536066.2 | F17: =FV(0.015,1,0,-F16,0) -> 2248208.5 | G17: =FV(-0.01,1,0,-G16,0) -> 1111862 | H17: =F17-G17 -> 1136346.5 | I17: 3605542.3
A18: 48 | B18: 2029 | C18: =(FV(0.05,1,-(12*$B$2),-C17,0))+$B$5 -> 2509596.2 | D18: =((FV(0.05,1,-(0),-D17,0))+$B$5) -> 3070209.4 | E18: =((FV(0.05,1,-(0),-E17,0))+$B$5) -> 3912869.5 | F18: =FV(0.015,1,0,-F17,0) -> 2281931.6 | G18: =FV(-0.01,1,0,-G17,0) -> 1100743.4 | H18: =F18-G18 -> 1181188.3 | I18: 3937973.4
A19: 49 | B19: 2030 | C19: =(FV(0.05,1,-(12*$B$2),-C18,0))+$B$5 -> 2871076 | D19: =((FV(0.05,1,-(0),-D18,0))+$B$5) -> 3423719.9 | E19: =((FV(0.05,1,-(0),-E18,0))+$B$5) -> 4308513 | F19: =FV(0.015,1,0,-F18,0) -> 2316160.6 | G19: =FV(-0.01,1,0,-G18,0) -> 1089735.9 | H19: =F19-G19 -> 1226424.7 | I19: 4286424
A20: 50 | B20: 2031 | C20: =(FV(0.05,1,-(12*$B$2),-C19,0))+$B$5 -> 3250629.8 | D20: =((FV(0.05,1,-(0),-D19,0))+$B$5) -> 3794905.9 | E20: =((FV(0.05,1,-(0),-E19,0))+$B$5) -> 4723938.6 | F20: =FV(0.015,1,0,-F19,0) -> 2350903 | G20: =FV(-0.01,1,0,-G19,0) -> 1078838.6 | H20: =F20-G20 -> 1272064.4 | I20: 4651682.9
A21: 51 | B21: 2032 | C21: =(FV(0.05,1,-(12*$B$2),-C20,0))+$B$5 -> 3649161.3 | D21: =((FV(0.05,1,-(0),-D20,0))+$B$5) -> 4184651.2 | E21: =((FV(0.05,1,-(0),-E20,0))+$B$5) -> 5160135.6 | F21: =FV(0.015,1,0,-F20,0) -> 2386166.6 | G21: =FV(-0.01,1,0,-G20,0) -> 1068050.2 | H21: =F21-G21 -> 1318116.4 | I21: 5034578.3
A22: 52 | B22: 2033 | C22: =(FV(0.05,1,-(12*$B$2),-C21,0))+$B$5 -> 4067619.4 | D22: =((FV(0.05,1,-(0),-D21,0))+$B$5) -> 4593883.7 | E22: =((FV(0.05,1,-(0),-E21,0))+$B$5) -> 5618142.3 | F22: =FV(0.015,1,0,-F21,0) -> 2421959.1 | G22: =FV(-0.01,1,0,-G21,0) -> 1057369.7 | H22: =F22-G22 -> 1364589.4 | I22: 5435979.4
A23: 53 | B23: 2034 | C23: =(FV(0.05,1,-(12*$B$2),-C22,0))+$B$5 -> 4507000.3 | D23: =((FV(0.05,1,-(0),-D22,0))+$B$5) -> 5023577.9 | E23: =((FV(0.05,1,-(0),-E22,0))+$B$5) -> 6099049.5 | F23: =FV(0.015,1,0,-F22,0) -> 2458288.4 | G23: =FV(-0.01,1,0,-G22,0) -> 1046796 | H23: =F23-G23 -> 1411492.4 | I23: 5856798.8
A24: 54 | B24: 2035 | C24: =(FV(0.05,1,-(12*$B$2),-C23,0))+$B$5 -> 4968350.4 | D24: =((FV(0.05,1,-(0),-D23,0))+$B$5) -> 5474756.8 | E24: =((FV(0.05,1,-(0),-E23,0))+$B$5) -> 6604001.9 | F24: =FV(0.015,1,0,-F23,0) -> 2495162.8 | G24: =FV(-0.01,1,0,-G23,0) -> 1036328 | H24: =F24-G24 -> 1458834.7 | I24: 6297994.3
A25: 55 | B25: 2036 | C25: =(FV(0.05,1,-(12*$B$2),-C24,0))+$B$5 -> 5452767.9 | D25: =((FV(0.05,1,-(0),-D24,0))+$B$5) -> 5948494.7 | E25: =((FV(0.05,1,-(0),-E24,0))+$B$5) -> 7134202 | F25: =FV(0.015,1,0,-F24,0) -> 2532590.2 | G25: =FV(-0.01,1,0,-G24,0) -> 1025964.8 | H25: =F25-G25 -> 1506625.5 | I25: 6760571.5
A26: 56 | B26: 2037 | C26: =(FV(0.025,1,-(12*$B$2),-C25,0))+$B$5 -> 5825087.1 | D26: =(FV(0.025,1,0,-D25,0))-200000 -> 5897207 | E26: =(FV(0.025,1,0,-E25,0))-$B$7 -> 6912557.1 | F26: =FV(0.015,1,0,-F25,0) -> 2570579.1 | G26: =FV(-0.01,1,0,-G25,0) -> 1015705.1 | H26: =F26-G26 -> 1554874 | I26: 7245585.9
A27: 57 | B27: 2038 | C27: =(FV(0.025,1,-(12*$B$2),-C26,0))+$B$5 -> 6206714.2 | D27: =(FV(0.025,1,0,-D26,0))-200000 -> 5844637.2 | E27: =(FV(0.025,1,0,-E26,0))-$B$7 -> 6685371 | F27: =FV(0.015,1,0,-F26,0) -> 2609137.8 | G27: 0 | H27: =F27-G27 -> 2609137.8 | I27: 7754145.5
A28: 58 | B28: 2039 | C28: =(FV(0.025,1,-(12*$B$2),-C27,0))+$B$5 -> 6597882.1 | D28: =(FV(0.025,1,0,-D27,0))-200000 -> 5790753.1 | E28: =(FV(0.025,1,0,-E27,0))-$B$7 -> 6452505.3 | F28: =FV(0.015,1,0,-F27,0) -> 2648274.8 | G28: 0 | H28: =F28-G28 -> 2648274.8 | I28: 8287413.4
A29: 59 | B29: 2040 | C29: =(FV(0.025,1,-(12*$B$2),-C28,0))+$B$5 -> 6998829.2 | D29: =(FV(0.025,1,0,-D28,0))-200000 -> 5735522 | E29: =(FV(0.025,1,0,-E28,0))-$B$7 -> 6213817.9 | F29: =FV(0.015,1,0,-F28,0) -> 2687998.9 | G29: 0 | H29: =F29-G29 -> 2687998.9 | I29: 8846610.7
A30: 60 | B30: 2041 | C30: =(FV(0.025,1,-(12*$B$2),-C29,0))+$B$5 -> 7409799.9 | D30: =(FV(0.025,1,0,-D29,0))-200000 -> 5678910 | E30: =(FV(0.025,1,0,-E29,0))-$B$7 -> 5969163.4 | F30: =FV(0.015,1,0,-F29,0) -> 2728318.9 | G30: 0 | H30: =F30-G30 -> 2728318.9 | I30: 9433019.2
A31: 61 | B31: 2042 | C31: =(FV(0.025,1,-(12*$B$2),-C30,0))+$B$5 -> 7831044.9 | D31: =(FV(0.025,1,0,-D30,0))-200000 -> 5620882.8 | E31: =(FV(0.025,1,0,-E30,0))-$B$7 -> 5718392.4 | F31: =FV(0.015,1,0,-F30,0) -> 2769243.7 | G31: 0 | H31: =F31-G31 -> 2769243.7 | I31: 10047984
A32: 62 | B32: 2043 | C32: =(FV(0.025,1,-(12*$B$2),-C31,0))+$B$5 -> 8262821 | D32: =(FV(0.025,1,0,-D31,0))-200000 -> 5561404.8 | E32: =(FV(0.025,1,0,-E31,0))-$B$7 -> 5461352.2 | F32: =FV(0.015,1,0,-F31,0) -> 2810782.4 | G32: 0 | H32: =F32-G32 -> 2810782.4 | I32: 10692919
A33: 63 | B33: 2044 | C33: =(FV(0.025,1,-(12*$B$2),-C32,0))+$B$5 -> 8705391.5 | D33: =(FV(0.025,1,0,-D32,0))-200000 -> 5500439.9 | E33: =(FV(0.025,1,0,-E32,0))-$B$7 -> 5197886.1 | F33: =FV(0.015,1,0,-F32,0) -> 2852944.1 | G33: 0 | H33: =F33-G33 -> 2852944.1 | I33: 11369306
A34: 64 | B34: 2045 | C34: =(FV(0.025,1,-(12*$B$2),-C33,0))+$B$5 -> 9159026.3 | D34: =(FV(0.025,1,0,-D33,0))-200000 -> 5437950.9 | E34: =(FV(0.025,1,0,-E33,0))-$B$7 -> 4927833.2 | F34: =FV(0.015,1,0,-F33,0) -> 2895738.3 | G34: 0 | H34: =F34-G34 -> 2895738.3 | I34: 12078701
A35: 65 | B35: 2046 | C35: =(FV(0.025,1,-(12*$B$2),-C34,0))+$B$5 -> 9624002 | D35: =(FV(0.025,1,0,-D34,0))-200000 -> 5373899.7 | E35: =(FV(0.025,1,0,-E34,0))-$B$7 -> 4651029 | F35: =FV(0.015,1,0,-F34,0) -> 2939174.3 | G35: 0 | H35: =F35-G35 -> 2939174.3 | I35: 12822740
A36: 66 | B36: 2047 | C36: =(FV(0.025,1,-(12*$B$2),-C35,0))+$B$5 -> 10100602 | D36: =(FV(0.025,1,0,-D35,0))-200000 -> 5308247.2 | E36: =(FV(0.025,1,0,-E35,0))-$B$7 -> 4367304.8 | F36: =FV(0.015,1,0,-F35,0) -> 2983262 | G36: 0 | H36: =F36-G36 -> 2983262 | I36: 13445826
A37: 67 | B37: 2048 | C37: =(FV(0.025,1,-(12*$B$2),-C36,0))+$B$5 -> 10589117 | D37: =(FV(0.025,1,0,-D36,0))-200000 -> 5240953.4 | E37: =(FV(0.025,1,0,-E36,0))-$B$7 -> 4076487.4 | F37: =FV(0.015,1,0,-F36,0) -> 3028010.9 | G37: 0 | H37: =F37-G37 -> 3028010.9 | I37: 14123459
A38: 68 | B38: 2049 | C38: =(FV(0.025,1,-(12*$B$2),-C37,0))+$B$5 -> 11089845 | D38: =(FV(0.025,1,0,-D37,0))-200000 -> 5171977.2 | E38: =(FV(0.025,1,0,-E37,0))-$B$7 -> 3778399.6 | F38: =FV(0.015,1,0,-F37,0) -> 3073431 | G38: 0 | H38: =F38-G38 -> 3073431 | I38: 14801091
... A44: 74 | B44: 2055 | C44: =(FV(0.025,1,-(12*$B$2),-C43,0))+$B$5 -> 14368326 | D44: =(FV(0.025,1,0,-D43,0))-200000 -> 4720360.6 | E44: =(FV(0.025,1,0,-E43,0))-$B$7 -> 1826690.4 | F44: =FV(0.015,1,0,-F43,0) -> 3360622.5 | G44: 0 | H44: =F44-G44 -> 3360622.5 | I44: 18866887
A45: 75 | B45: 2056 | C45: =(FV(0.025,1,-(12*$B$2),-C44,0))+$B$5 -> 14963534 | D45: =(FV(0.025,1,0,-D44,0))-200000 -> 4638369.6 | E45: =(FV(0.025,1,0,-E44,0))-$B$8 -> 1672357.7 | F45: =FV(0.015,1,0,-F44,0) -> 3411031.8 | G45: 0 | H45: =F45-G45 -> 3411031.8 | I45: 19544520
A46: 76 | B46: 2057 | C46: =(FV(0.025,1,-(12*$B$2),-C45,0))+$B$5 -> 15573623 | D46: =(FV(0.025,1,0,-D45,0))-125000 -> 4629328.9 | E46: =(FV(0.025,1,0,-E45,0))-$B$8 -> 1514166.6 | F46: =FV(0.015,1,0,-F45,0) -> 3462197.3 | G46: 0 | H46: =F46-G46 -> 3462197.3 | I46: 20222152
A47: 77 | B47: 2058 | C47: =(FV(0.025,1,-(12*$B$2),-C46,0))+$B$5 -> 16198963 | D47: =(FV(0.025,1,0,-D46,0))-125000 -> 4620062.1 | E47: =(FV(0.025,1,0,-E46,0))-$B$8 -> 1352020.8 | F47: =FV(0.015,1,0,-F46,0) -> 3514130.2 | G47: 0 | H47: =F47-G47 -> 3514130.2 | I47: 20899785
...

Sheet Investment Performance
A1: Type | B1: Account | C1: 2023 | D1: 2024 | E1: 2025
A2: Benchmark | B2: S&P 500 | C2: 0.2625 | D2: 0.2494 | E2: 0.178
A3: Benchmark | B3: Whole Market (Vanguard VTI) | C3: 0.2611 | D3: 0.2371 | E3: 0.171
A4: Benchmark | B4: Whole Canadian Market | C4: 0.122 | D4: 0.223 | E4: 0.3092
A5: Managed | B5: RBC WM | C5: =(SUM('Net Worth Monthly'!G18:G21)-SUM('Net Worth Monthly'!B18:B21))/SUM('Net Worth Monthly'!B18:B21) -> 0.31438707 | D5: =(SUM('Net Worth Monthly'!K18:K21)-SUM('Net Worth Monthly'!H18:H21))/SUM('Net Worth Monthly'!H18:H21) -> 0.19125949 | E5: =(SUM('Net Worth Monthly'!P18:P21)-SUM('Net Worth Monthly'!L18:L21))/SUM('Net Worth Monthly'!L18:L21) -> 0.04721335
A6: Retirement | B6: Sunlife | C6: ='Net Worth Monthly'!B36 | E6: ='Net Worth Monthly'!D36
A7: US Retirement | B7: Fidelity | C7: =('Net Worth Monthly'!G16-'Net Worth Monthly'!B16)/'Net Worth Monthly'!B16 -> 0.18279167 | D7: =('Net Worth Monthly'!K16-'Net Worth Monthly'!H16)/'Net Worth Monthly'!H16 -> 0.93984814 | E7: =('Net Worth Monthly'!P16-'Net Worth Monthly'!L16)/'Net Worth Monthly'!L16 -> 0.26881567
A8: US Retirement | B8: Lisa 401K | C8: =('Net Worth Monthly'!G22-'Net Worth Monthly'!B22)/'Net Worth Monthly'!B22 -> 0.21667312 | D8: =('Net Worth Monthly'!K22-'Net Worth Monthly'!H22)/'Net Worth Monthly'!H22 -> 1.1303258 | E8: =('Net Worth Monthly'!P22-'Net Worth Monthly'!L22)/'Net Worth Monthly'!L22 -> 0.060350254
A9: Self-DIrected | B9: Questrade | C9: =('Net Worth Monthly'!G17-'Net Worth Monthly'!B17)/'Net Worth Monthly'!B17 -> 0.12634783 | D9: =('Net Worth Monthly'!K17-'Net Worth Monthly'!H17)/'Net Worth Monthly'!H17 -> 0.19260584 | E9: =('Net Worth Monthly'!P17-'Net Worth Monthly'!L17)/'Net Worth Monthly'!L17 -> 0.13777737
